Workbook

Sheet TRANSFERY od 01.2019
A1: L.p. | B1: w / z | C1: Nazwisko i imię | D1: ID | E1: Stan. | F1: Obszar** | G1: CC | H1: Przełożony | I1: Obszar | J1: CC | K1: Przełożony | L1: Data transferu | M1: Data spotkania | N1: Ilość dni | O1: Data wpłynięcia wniosku | P1: Status | Q1: Rodzaj transferu (Stały / Czasowy) | R1: Data powrotu na poprzedni obszar | S1: Powód transferu czasowego | T1: Data ostatniego transferu | U1: Ilość dni | V1: Uzasadnienie transferu stałego | W1: Komentarz | X1: IL. TRANSFERÓW | Y1: ZEW / WEW | Z1: KOM | AA1: CHECK
A2: 1 | B2: W | C2: =VLOOKUP(D2,'lista 1'!$A$2:$F3520,4,0) -> SWAŁTEK BENIAMIN | D2: 402 | E2: =VLOOKUP(D2,'lista 1'!$A$2:$F$1802,5,0) -> AGM | F2: =VLOOKUP(G2,'lista obszary'!A:B,2,0) -> Production Management | G2: G0146 | H2: FIGZAŁ CEZARY | I2: =VLOOKUP(J2,'lista obszary'!A:B,2,0) -> Production Management | J2: G0350 | K2: FIGZAŁ CEZARY | L2: 2019-01-01 | P2: zrealizowany | Q2: STAŁY | U2: =L2-T2 -> 43466 | X2: =VLOOKUP(D2,#REF!,2,0) -> #REF! | Y2: WEW
A3: 2 | B3: Z | C3: =VLOOKUP(D3,'lista 1'!$A$2:$F3521,4,0) -> CICHOWICZ MARIUSZ | D3: 360 | E3: GRL | F3: =VLOOKUP(G3,'lista obszary'!A:B,2,0) -> ENGINES | G3: G613A | H3: MUSIAŁ GRZEGORZ | I3: =VLOOKUP(J3,'lista obszary'!A:B,2,0) -> HV | J3: V1020 | K3: KALINOWSKI GRZEGORZ | L3: 2019-01-01 | P3: zrealizowany | Q3: CZASOWY | U3: =L3-T3 -> 43466 | X3: =VLOOKUP(D3,#REF!,2,0) -> #REF! | Y3: =F3=I3 -> FALSE
A4: 3 | B4: W | C4: =VLOOKUP(D4,'lista 1'!$A$2:$F3522,4,0) -> #N/A | D4: 64215 | E4: =VLOOKUP(D4,'lista 1'!$A$2:$F$1802,5,0) -> #N/A | F4: =VLOOKUP(G4,'lista obszary'!A:B,2,0) -> IL | G4: E112C | H4: GIERCZAK KRZYSZTOF | I4: =VLOOKUP(J4,'lista obszary'!A:B,2,0) -> IL | J4: E31VA | K4: WESOŁEK WIESŁAW | L4: 2019-01-02 | P4: zrealizowany | U4: =L4-T4 -> 43467 | X4: =VLOOKUP(D4,#REF!,2,0) -> #REF! | Y4: WEW
A5: 4 | B5: W | C5: =VLOOKUP(D5,'lista 1'!$A$2:$F3523,4,0) -> SMĘTKOWSKI SŁAWOMIR | D5: 1359 | E5: TM2 | F5: =VLOOKUP(G5,'lista obszary'!A:B,2,0) -> IL | G5: E113A | H5: ZIEMNIAK GRZEGORZ | I5: =VLOOKUP(J5,'lista obszary'!A:B,2,0) -> IL | J5: E112A | K5: ZIEMNIAK GRZEGORZ | L5: 2019-01-02 | P5: zrealizowany | U5: =L5-T5 -> 43467 | X5: =VLOOKUP(D5,#REF!,2,0) -> #REF! | Y5: =F5=I5 -> TRUE
A6: 5 | B6: W | C6: =VLOOKUP(D6,'lista 1'!$A$2:$F3524,4,0) -> #N/A | D6: 64333 | E6: TCZ | F6: =VLOOKUP(G6,'lista obszary'!A:B,2,0) -> IL | G6: E31VA | H6: WESOŁEK WIESŁAW | I6: =VLOOKUP(J6,'lista obszary'!A:B,2,0) -> IL | J6: E113C | K6: GIERCZAK KRZYSZTOF | L6: 2019-01-02 | P6: zrealizowany | U6: =L6-T6 -> 43467 | X6: =VLOOKUP(D6,#REF!,2,0) -> #REF! | Y6: WEW
A7: 6 | B7: W | C7: =VLOOKUP(D7,'lista 1'!$A$2:$F3525,4,0) -> JAGODZIŃSKI KAZIMIERZ | D7: 11 | E7: =VLOOKUP(D7,'lista 1'!$A$2:$F$1802,5,0) -> GM | F7: =VLOOKUP(G7,'lista obszary'!A:B,2,0) -> Production Management | G7: G0350 | H7: HIGAKI SHUJI | I7: =VLOOKUP(J7,'lista obszary'!A:B,2,0) -> Production Management | J7: G0001 | K7: USAMI SHINJI | L7: 2019-01-02 | P7: zrealizowany | U7: =L7-T7 -> 43467 | X7: =VLOOKUP(D7,#REF!,2,0) -> #REF! | Y7: WEW
A8: 7 | B8: W | C8: =VLOOKUP(D8,'lista 1'!$A$2:$F3526,4,0) -> #N/A | D8: 64328 | E8: =VLOOKUP(D8,'lista 1'!$A$2:$F$1802,5,0) -> #N/A | F8: =VLOOKUP(G8,'lista obszary'!A:B,2,0) -> FORGING | G8: G302B | H8: KOŁOWIECKI SŁAWOMIR | I8: =VLOOKUP(J8,'lista obszary'!A:B,2,0) -> FORGING | J8: G303B | K8: RYCZEK SEBASTIAN | L8: 2019-01-02 | P8: zrealizowany | U8: =L8-T8 -> 43467 | X8: =VLOOKUP(D8,#REF!,2,0) -> #REF! | Y8: WEW
A9: 8 | B9: Z | C9: =VLOOKUP(D9,'lista 1'!$A$2:$F3527,4,0) -> ANTONIEWICZ ANNA | D9: 2111 | E9: =VLOOKUP(D9,'lista 1'!$A$2:$F$1802,5,0) -> TM | F9: =VLOOKUP(G9,'lista obszary'!A:B,2,0) -> MTB0 | G9: G401A | H9: PEREK KRZYSZTOF | I9: =VLOOKUP(J9,'lista obszary'!A:B,2,0) -> HV | J9: V1020 | K9: MAŁECKI KRZYSZTOF | L9: 2019-01-02 | P9: zrealizowany | U9: =L9-T9 -> 43467 | X9: =VLOOKUP(D9,#REF!,2,0) -> #REF! | Y9: =F9=I9 -> FALSE
A10: 9 | B10: Z | C10: =VLOOKUP(D10,'lista 1'!$A$2:$F3528,4,0) -> SUSZEK MIROSŁAW | D10: 252 | E10: TL | F10: =VLOOKUP(G10,'lista obszary'!A:B,2,0) -> MTB0 | G10: G401A | H10: CZYŻOWSKI MARIUSZ | I10: =VLOOKUP(J10,'lista obszary'!A:B,2,0) -> DOJO/QCC/KAIZEN | J10: S0001 | K10: KAŁUŻYŃSKI MIROSŁAW | L10: 2019-01-02 | P10: zrealizowany | U10: =L10-T10 -> 43467 | X10: =VLOOKUP(D10,#REF!,2,0) -> #REF! | Y10: ZEW PRZED 01.07
A11: 10 | B11: Z | C11: =VLOOKUP(D11,'lista 1'!$A$2:$F3529,4,0) -> OLEŚ MAŁGORZATA | D11: 2308 | E11: TM | F11: =VLOOKUP(G11,'lista obszary'!A:B,2,0) -> MTB0 | G11: G405B | H11: CZUCZUK PIOTR | I11: =VLOOKUP(J11,'lista obszary'!A:B,2,0) -> HV | J11: V102B | K11: KUBAL PIOTR | L11: 2019-01-02 | P11: zrealizowany | U11: =L11-T11 -> 43467 | X11: =VLOOKUP(D11,#REF!,2,0) -> #REF! | Y11: =F11=I11 -> FALSE
A12: 11 | B12: W | C12: =VLOOKUP(D12,'lista 1'!$A$2:$F3530,4,0) -> BĘDZIŃSKI MARIUSZ | D12: 2196 | E12: TM | F12: =VLOOKUP(G12,'lista obszary'!A:B,2,0) -> CASTING | G12: G501A | H12: ŚLUCZKA TYMOTEUSZ | I12: =VLOOKUP(J12,'lista obszary'!A:B,2,0) -> CASTING | J12: G501B | K12: PIOTROWSKI WOJCIECH | L12: 2019-01-02 | P12: zrealizowany | U12: =L12-T12 -> 43467 | X12: =VLOOKUP(D12,#REF!,2,0) -> #REF! | Y12: =F12=I12 -> TRUE
A13: 12 | B13: W | C13: =VLOOKUP(D13,'lista 1'!$A$2:$F3531,4,0) -> HURKOT PIOTR | D13: 1302 | E13: =VLOOKUP(D13,'lista 1'!$A$2:$F$1802,5,0) -> TM2 | F13: =VLOOKUP(G13,'lista obszary'!A:B,2,0) -> CASTING | G13: G501A | H13: ŚLUCZKA TYMOTEUSZ | I13: =VLOOKUP(J13,'lista obszary'!A:B,2,0) -> CASTING | J13: G501B | K13: PIOTROWSKI WOJCIECH | L13: 2019-01-02 | P13: zrealizowany | U13: =L13-T13 -> 43467 | X13: =VLOOKUP(D13,#REF!,2,0) -> #REF! | Y13: =F13=I13 -> TRUE
A14: 13 | B14: W | C14: =VLOOKUP(D14,'lista 1'!$A$2:$F3532,4,0) -> KAŁENDEK DAMIAN | D14: 2150 | E14: TM2 | F14: =VLOOKUP(G14,'lista obszary'!A:B,2,0) -> CASTING | G14: G501A | H14: ŚLUCZKA TYMOTEUSZ | I14: =VLOOKUP(J14,'lista obszary'!A:B,2,0) -> CASTING | J14: G501B | K14: PIOTROWSKI WOJCIECH | L14: 2019-01-02 | P14: zrealizowany | U14: =L14-T14 -> 43467 | X14: =VLOOKUP(D14,#REF!,2,0) -> #REF! | Y14: ZEWNĘTRZNY PO 01.07
A15: 14 | B15: W | C15: =VLOOKUP(D15,'lista 1'!$A$2:$F3533,4,0) -> KOWALCZYK TOMASZ | D15: 1401 | E15: TM2 | F15: =VLOOKUP(G15,'lista obszary'!A:B,2,0) -> CASTING | G15: G501A | H15: ŚLUCZKA TYMOTEUSZ | I15: =VLOOKUP(J15,'lista obszary'!A:B,2,0) -> CASTING | J15: G501B | K15: PIOTROWSKI WOJCIECH | L15: 2019-01-02 | P15: zrealizowany | U15: =L15-T15 -> 43467 | X15: =VLOOKUP(D15,#REF!,2,0) -> #REF! | Y15: WEW
A16: 15 | B16: W | C16: =VLOOKUP(D16,'lista 1'!$A$2:$F3534,4,0) -> KRYCH RAFAŁ | D16: 1317 | E16: TM2 | F16: =VLOOKUP(G16,'lista obszary'!A:B,2,0) -> CASTING | G16: G501A | H16: ŚLUCZKA TYMOTEUSZ | I16: =VLOOKUP(J16,'lista obszary'!A:B,2,0) -> CASTING | J16: G501B | K16: PIOTROWSKI WOJCIECH | L16: 2019-01-02 | P16: zrealizowany | U16: =L16-T16 -> 43467 | X16: =VLOOKUP(D16,#REF!,2,0) -> #REF! | Y16: =F16=I16 -> TRUE
A17: 16 | B17: W | C17: =VLOOKUP(D17,'lista 1'!$A$2:$F3535,4,0) -> #N/A | D17: 64222 | E17: =VLOOKUP(D17,'lista 1'!$A$2:$F$1802,5,0) -> #N/A | F17: =VLOOKUP(G17,'lista obszary'!A:B,2,0) -> CASTING | G17: G501A | H17: ŚLUCZKA TYMOTEUSZ | I17: =VLOOKUP(J17,'lista obszary'!A:B,2,0) -> CASTING | J17: G501B | K17: PIOTROWSKI WOJCIECH | L17: 2019-01-02 | P17: zrealizowany | U17: =L17-T17 -> 43467 | X17: =VLOOKUP(D17,#REF!,2,0) -> #REF! | Y17: WEW
A18: 17 | B18: W | C18: =VLOOKUP(D18,'lista 1'!$A$2:$F3536,4,0) -> BUDZYŃSKI JACEK | D18: 155 | E18: TL2 | F18: =VLOOKUP(G18,'lista obszary'!A:B,2,0) -> CASTING | G18: G5020 | H18: BALON PIOTR | I18: =VLOOKUP(J18,'lista obszary'!A:B,2,0) -> CASTING | J18: G501A | K18: ŚLUCZKA TYMOTEUSZ | L18: 2019-01-02 | P18: zrealizowany | U18: =L18-T18 -> 43467 | X18: =VLOOKUP(D18,#REF!,2,0) -> #REF! | Y18: WEW
A19: 18 | B19: W | C19: =VLOOKUP(D19,'lista 1'!$A$2:$F3537,4,0) -> #N/A | D19: 64359 | E19: TCZ | F19: =VLOOKUP(G19,'lista obszary'!A:B,2,0) -> CASTING | G19: G5020 | H19: BALON PIOTR | I19: =VLOOKUP(J19,'lista obszary'!A:B,2,0) -> CASTING | J19: G501A | K19: ŚLUCZKA TYMOTEUSZ | L19: 2019-01-02 | P19: zrealizowany | U19: =L19-T19 -> 43467 | X19: =VLOOKUP(D19,#REF!,2,0) -> #REF! | Y19: =F19=I19 -> TRUE
A20: 19 | B20: W | C20: =VLOOKUP(D20,'lista 1'!$A$2:$F3538,4,0) -> #N/A | D20: 70433 | E20: TCZ | F20: =VLOOKUP(G20,'lista obszary'!A:B,2,0) -> CASTING | G20: G5020 | H20: BALON PIOTR | I20: =VLOOKUP(J20,'lista obszary'!A:B,2,0) -> CASTING | J20: G501B | K20: PIOTROWSKI WOJCIECH | L20: 2019-01-02 | P20: zrealizowany | U20: =L20-T20 -> 43467 | X20: =VLOOKUP(D20,#REF!,2,0) -> #REF! | Y20: =F20=I20 -> TRUE
A21: 20 | B21: Z | C21: =VLOOKUP(D21,'lista 1'!$A$2:$F3539,4,0) -> KRYSTKOWIAK GRZEGORZ | D21: 706 | E21: TM | F21: =VLOOKUP(G21,'lista obszary'!A:B,2,0) -> ENGINES | G21: G611B | H21: DĄBROWSKI JAROSŁAW | I21: =VLOOKUP(J21,'lista obszary'!A:B,2,0) -> HV | J21: V1020 | K21: LUBORAK SŁAWOMIR | L21: 2019-01-02 | P21: zrealizowany | U21: =L21-T21 -> 43467 | X21: =VLOOKUP(D21,#REF!,2,0) -> #REF! | Y21: ZEWNĘTRZNY PO 01.07
A22: 21 | B22: Z | C22: =VLOOKUP(D22,'lista 1'!$A$2:$F3540,4,0) -> TAJS GRZEGORZ | D22: 2141 | E22: TM2 | F22: =VLOOKUP(G22,'lista obszary'!A:B,2,0) -> ENGINES | G22: G612A | H22: SAWUŁA KAMIL | I22: =VLOOKUP(J22,'lista obszary'!A:B,2,0) -> HV | J22: V1020 | K22: FOLKMAN SEBASTIAN | L22: 2019-01-02 | P22: zrealizowany | U22: =L22-T22 -> 43467 | X22: =VLOOKUP(D22,#REF!,2,0) -> #REF! | Y22: =F22=I22 -> FALSE
A23: 22 | B23: Z | C23: =VLOOKUP(D23,'lista 1'!$A$2:$F3541,4,0) -> MASKO PAWEŁ | D23: 216 | E23: TL2 | F23: =VLOOKUP(G23,'lista obszary'!A:B,2,0) -> ENGINES | G23: G615B | H23: BADIURA KRZYSZTOF | I23: =VLOOKUP(J23,'lista obszary'!A:B,2,0) -> BENKYOKAI | J23: T0002 | K23: DEPTALSKI JAROSŁAW | L23: 2019-01-02 | P23: BADANIA | U23: =L23-T23 -> 43467 | X23: =VLOOKUP(D23,#REF!,2,0) -> #REF! | Y23: =F23=I23 -> FALSE
A24: 23 | B24: W | C24: =VLOOKUP(D24,'lista 1'!$A$2:$F3542,4,0) -> PICEK KRZYSZTOF | D24: 960 | E24: ASM | F24: =VLOOKUP(G24,'lista obszary'!A:B,2,0) -> MNX OFFICE | G24: G7000 | H24: NAWROCKI WITOLD | I24: =VLOOKUP(J24,'lista obszary'!A:B,2,0) -> MNX | J24: G7100 | K24: KOWALSKI TOMASZ | L24: 2019-01-02 | P24: zrealizowany | U24: =L24-T24 -> 43467 | X24: =VLOOKUP(D24,#REF!,2,0) -> #REF! | Y24: ZEW PRZED 01.07
A25: 24 | B25: Z | C25: =VLOOKUP(D25,'lista 1'!$A$2:$F3543,4,0) -> SZCZĘSNY GRZEGORZ | D25: 639 | E25: TM2 | F25: =VLOOKUP(G25,'lista obszary'!A:B,2,0) -> MNX MW | G25: G718A | H25: KOPEĆ | I25: =VLOOKUP(J25,'lista obszary'!A:B,2,0) -> EC60 | J25: G803A | K25: TOKARSKI ARTUR | L25: 2019-01-02 | P25: zrealizowany | U25: =L25-T25 -> 43467 | X25: =VLOOKUP(D25,#REF!,2,0) -> #REF! | Y25: ZEW PRZED 01.07
A26: 25 | B26: W | C26: =VLOOKUP(D26,'lista 1'!$A$2:$F3544,4,0) -> MEROŃ STEFAN | D26: 367 | E26: TM MNX2 | F26: =VLOOKUP(G26,'lista obszary'!A:B,2,0) -> MNX | G26: G7944 | H26: ZĘBEK ANDRZEJ | I26: =VLOOKUP(J26,'lista obszary'!A:B,2,0) -> MNX WN | J26: G7715 | K26: ZĘBEK ANDRZEJ | L26: 2019-01-02 | P26: zrealizowany | U26: =L26-T26 -> 43467 | X26: =VLOOKUP(D26,#REF!,2,0) -> #REF! | Y26: WEW
A27: 26 | B27: W | C27: =VLOOKUP(D27,'lista 1'!$A$2:$F3545,4,0) -> OSIŃSKI TOMASZ | D27: 887 | E27: TL MNX | F27: =VLOOKUP(G27,'lista obszary'!A:B,2,0) -> MNX | G27: G7944 | H27: ZĘBEK ANDRZEJ | I27: =VLOOKUP(J27,'lista obszary'!A:B,2,0) -> MNX WN | J27: G7715 | K27: ZĘBEK ANDRZEJ | L27: 2019-01-02 | P27: zrealizowany | U27: =L27-T27 -> 43467 | X27: =VLOOKUP(D27,#REF!,2,0) -> #REF! | Y27: WEW
A28: 27 | B28: W | C28: =VLOOKUP(D28,'lista 1'!$A$2:$F3546,4,0) -> PASTERNAK MARIUSZ | D28: 234 | E28: GRL MNX2 | F28: =VLOOKUP(G28,'lista obszary'!A:B,2,0) -> MNX | G28: G7944 | H28: ZĘBEK ANDRZEJ | I28: =VLOOKUP(J28,'lista obszary'!A:B,2,0) -> MNX WN | J28: G7715 | K28: ZĘBEK ANDRZEJ | L28: 2019-01-02 | P28: zrealizowany | U28: =L28-T28 -> 43467 | X28: =VLOOKUP(D28,#REF!,2,0) -> #REF! | Y28: WEW
A29: 28 | B29: W | C29: =VLOOKUP(D29,'lista 1'!$A$2:$F3547,4,0) -> #N/A | D29: 2125 | E29: TM MNX2 | F29: =VLOOKUP(G29,'lista obszary'!A:B,2,0) -> MNX | G29: G7944 | H29: ZĘBEK ANDRZEJ | I29: =VLOOKUP(J29,'lista obszary'!A:B,2,0) -> MNX WN | J29: G7715 | K29: ZĘBEK ANDRZEJ | L29: 2019-01-02 | P29: zrealizowany | U29: =L29-T29 -> 43467 | X29: =VLOOKUP(D29,#REF!,2,0) -> #REF! | Y29: WEW
A30: 29 | B30: Z | C30: =VLOOKUP(D30,'lista 1'!$A$2:$F3548,4,0) -> MIKA PIOTR | D30: 921 | E30: TL2 | F30: =VLOOKUP(G30,'lista obszary'!A:B,2,0) -> EC60 | G30: G801A | H30: KLECHA PRZEMYSŁAW | I30: =VLOOKUP(J30,'lista obszary'!A:B,2,0) -> HV PJT | J30: V201A | K30: CHRZANOWSKI JAROSŁAW | L30: 2019-01-02 | P30: zrealizowany | U30: =L30-T30 -> 43467 | X30: =VLOOKUP(D30,#REF!,2,0) -> #REF! | Y30: ZEW PRZED 01.07
A31: 30 | B31: W | C31: =VLOOKUP(D31,'lista 1'!$A$2:$F3549,4,0) -> TOKARSKI ARTUR | D31: 180 | E31: GRL | F31: =VLOOKUP(G31,'lista obszary'!A:B,2,0) -> EC60 | G31: G803A | H31: KOMORNICZAK MACIEJ | I31: =VLOOKUP(J31,'lista obszary'!A:B,2,0) -> EC60 | J31: G804A | K31: KOMORNICZAK MACIEJ | L31: 2019-01-02 | P31: zrealizowany | U31: =L31-T31 -> 43467 | X31: =VLOOKUP(D31,#REF!,2,0) -> #REF! | Y31: WEW
A32: 31 | B32: Z | C32: =VLOOKUP(D32,'lista 1'!$A$2:$F3550,4,0) -> CHRZANOWSKI JAROSŁAW | D32: 92 | E32: GRL | F32: =VLOOKUP(G32,'lista obszary'!A:B,2,0) -> EC60 | G32: G804A | H32: KOMORNICZAK MACIEJ | I32: =VLOOKUP(J32,'lista obszary'!A:B,2,0) -> HV PJT | J32: V201A | K32: WOJTAL MATEUSZ | L32: 2019-01-02 | P32: zrealizowany | U32: =L32-T32 -> 43467 | X32: =VLOOKUP(D32,#REF!,2,0) -> #REF! | Y32: ZEW PRZED 01.07
A33: 32 | B33: Z | C33: =VLOOKUP(D33,'lista 1'!$A$2:$F3551,4,0) -> KOTOWSKI KACPER | D33: 3009 | E33: JTM MNX | F33: =VLOOKUP(G33,'lista obszary'!A:B,2,0) -> EC60 | G33: G804A | H33: CHRZANOWSKI JAROSŁAW | I33: =VLOOKUP(J33,'lista obszary'!A:B,2,0) -> MNX WN | J33: G711C | K33: FIGIEL ROBERT | L33: 2019-01-02 | P33: zrealizowany | U33: =L33-T33 -> 43467 | X33: =VLOOKUP(D33,#REF!,2,0) -> #REF! | Y33: ZEW PRZED 01.07
A34: 33 | B34: Z | C34: =VLOOKUP(D34,'lista 1'!$A$2:$F3552,4,0) -> SZUPER TOMASZ | D34: 38 | E34: =VLOOKUP(D34,'lista 1'!$A$2:$F$1802,5,0) -> GRL2 | F34: =VLOOKUP(G34,'lista obszary'!A:B,2,0) -> EC60 | G34: G804A | H34: KOMORNICZAK MACIEJ | I34: =VLOOKUP(J34,'lista obszary'!A:B,2,0) -> HV PJT | J34: V203A | K34: WOJTAL MATEUSZ | L34: 2019-01-02 | P34: zrealizowany | U34: =L34-T34 -> 43467 | X34: =VLOOKUP(D34,#REF!,2,0) -> #REF! | Y34: ZEW PRZED 01.07
A35: 34 | B35: Z | C35: =VLOOKUP(D35,'lista 1'!$A$2:$F3553,4,0) -> SZYMKÓW PRZEMYSŁAW | D35: 33 | E35: GRL2 | F35: =VLOOKUP(G35,'lista obszary'!A:B,2,0) -> EC60 | G35: G8PRO | H35: SZKARADEK GRZEGORZ | I35: =VLOOKUP(J35,'lista obszary'!A:B,2,0) -> HV | J35: V1020 | K35: KALINOWSKI GRZEGORZ | L35: 2019-01-02 | P35: zrealizowany | U35: =L35-T35 -> 43467 | X35: =VLOOKUP(D35,#REF!,2,0) -> #REF! | Y35: WEW
A36: 35 | B36: W | C36: =VLOOKUP(D36,'lista 1'!$A$2:$F3554,4,0) -> ZĘBEK ANDRZEJ | D36: 1748 | E36: ASM | F36: =VLOOKUP(G36,'lista obszary'!A:B,2,0) -> ENGINEERING | G36: H2000 | H36: NAWROCKI WITOLD | I36: =VLOOKUP(J36,'lista obszary'!A:B,2,0) -> MNX OFFICE | J36: G7000 | K36: NAWROCKI WITOLD | L36: 2019-01-02 | P36: zrealizowany | U36: =L36-T36 -> 43467 | X36: =VLOOKUP(D36,#REF!,2,0) -> #REF! | Y36: ZEW PRZED 01.07
A37: 36 | B37: W | C37: =VLOOKUP(D37,'lista 1'!$A$2:$F3555,4,0) -> KOCUREK ŁUKASZ | D37: 2856 | E37: ENG | F37: =VLOOKUP(G37,'lista obszary'!A:B,2,0) -> ENGINEERING | G37: H2400 | H37: ZĘBEK ANDRZEJ | I37: =VLOOKUP(J37,'lista obszary'!A:B,2,0) -> ENGINEERING | J37: H2800 | K37: FIGIELA ROBERT | L37: 2019-01-02 | P37: zrealizowany | U37: =L37-T37 -> 43467 | X37: =VLOOKUP(D37,#REF!,2,0) -> #REF! | Y37: WEW
A38: 37 | B38: W | C38: =VLOOKUP(D38,'lista 1'!$A$2:$F3556,4,0) -> TATAREK TOMASZ | D38: 2857 | E38: ENG | F38: =VLOOKUP(G38,'lista obszary'!A:B,2,0) -> ENGINEERING | G38: H2600 | H38: ZĘBEK ANDRZEJ | I38: =VLOOKUP(J38,'lista obszary'!A:B,2,0) -> ENGINEERING | J38: H2600 | K38: PICEK KRZYSZTOF | L38: 2019-01-02 | P38: zrealizowany | U38: =L38-T38 -> 43467 | X38: =VLOOKUP(D38,#REF!,2,0) -> #REF! | Y38: WEW
A39: 38 | B39: W | C39: =VLOOKUP(D39,'lista 1'!$A$2:$F3557,4,0) -> NYKIEL ARTUR | D39: 581 | E39: ENG | F39: =VLOOKUP(G39,'lista obszary'!A:B,2,0) -> ENGINEERING | G39: H2800 | H39: ZĘBEK ANDRZEJ | I39: =VLOOKUP(J39,'lista obszary'!A:B,2,0) -> ENGINEERING | J39: H2400 | K39: FIGIELA ROBERT | L39: 2019-01-02 | P39: zrealizowany | U39: =L39-T39 -> 43467 | X39: =VLOOKUP(D39,#REF!,2,0) -> #REF! | Y39: WEW
A40: 39 | B40: Z | C40: =VLOOKUP(D40,'lista 1'!$A$2:$F3558,4,0) -> GŁÓD ARTUR | D40: 96 | E40: =VLOOKUP(D40,'lista 1'!$A$2:$F$1802,5,0) -> GRL | F40: =VLOOKUP(G40,'lista obszary'!A:B,2,0) -> DOJO/QCC/KAIZEN | G40: S0001 | H40: BYRA ZBIGNIEW | I40: =VLOOKUP(J40,'lista obszary'!A:B,2,0) -> HV PJT | J40: V202A | K40: WOJTAL MATEUSZ | L40: 2019-01-02 | P40: zrealizowany | U40: =L40-T40 -> 43467 | X40: =VLOOKUP(D40,#REF!,2,0) -> #REF! | Y40: ZEW PRZED 01.07
...

Sheet TRANSFERY od 01.2020
A1: Nazwisko i imię | B1: ID | C1: Stan. | D1: Obszar** | E1: CC | F1: Przełożony | G1: Obszar | H1: CC | I1: Przełożony | J1: Data transferu | K1: komentarz
A2: KOKOCIŃSKI GRZEGORZ | B2: 854 | C2: TM MNX | D2: CASTING | E2: G502A | F2: PARZYCH PIOTR | G2: CASTING | H2: G503B | I2: PASTUSZKA ŁUKASZ | J2: 43831
A3: BIENIEK DARIUSZ | B3: 1994 | C3: TM MNX | D3: CASTING | E3: G502A | F3: ŚLUCZKA TYMOTEUSZ | G3: CASTING | H3: G504C | I3: KUBIAK RAFAŁ | J3: 43831
A4: KUCHARSKA AGATA | B4: 1787 | C4: ASM | D4: ENGINEERING | E4: H1000 | F4: MROZIŃSKI DAMIAN | G4: ENGINEERING | H4: H1000 | I4: MROZIŃSKI DAMIAN | J4: 43831
A5: LECHNIO ZBIGNIEW | B5: 2974 | C5: ENG | D5: ENGINEERING | E5: H1400 | F5: KUCHARSKA AGATA | G5: ENGINEERING | H5: H1800 | I5: KUCHARSKA AGATA | J5: 43831
A6: #N/A | B6: 64311 | C6: TCZ | D6: IL | E6: E31VB | F6: ZDEB MARCIN | G6: IL | H6: E31VA | I6: WEISS DARIUSZ | J6: 43831
A7: SZCZĘSNY RAFAŁ | B7: 422 | C7: TM | D7: IL | E7: E3SVA | F7: WROŃSKI ANDRZEJ | G7: IL | H7: E31VB | I7: ZDEB MARCIN | J7: 43831
A8: WARCHOŁ ANDRZEJ | B8: 407 | C8: ASM | D8: MNX TK | E8: G761B | F8: PICEK KRZYSZTOF | G8: MNX | H8: G7100 | I8: KOWALSKI TOMASZ | J8: 43831
A9: DUDA ROBERT | B9: 815 | C9: TM2 | D9: ENGINES | E9: G613A | F9: SZYMANOWSKI ANDZREJ | G9: MNX DM | H9: G714A | I9: ZIEMNIAK MARCIN | J9: 43831
A10: KMITA MARCIN | B10: 1105 | C10: TL MNX | D10: MNX KP | E10: G731A | F10: ZIAJA PIOTR | G10: MNX KP | H10: G731B | I10: STUS PAWEŁ | J10: 43831
A11: CIEŚLAK ZDZISŁAW | B11: 144 | C11: TL MNX2 | D11: MNX DM | E11: G714A | F11: ZIEMNIAK MARCIN | G11: MNX MW | H11: G718A | I11: KOPEĆ SŁAWOMIR | J11: 43831
A12: CIURA PAWEŁ | B12: 553 | C12: GRL MNX | D12: MNX KP | E12: G731B | F12: STUS PAWEŁ | G12: MNX TK | H12: G761B | I12: PICEK KRZYSZTOF | J12: 43831
A13: STARNAWSKI KRZYSZTOF | B13: 748 | C13: TL MNX | D13: MNX TK | E13: G761B | F13: ANDRZEJ WARCHOŁ | G13: MNX TK | H13: G761A | I13: ROMUALD PUZIAK | J13: 43831
A14: PRZYTOCKI DANIEL | B14: 784 | C14: TL MNX2 | D14: MNX TK | E14: G761D | F14: MARCIN PYŹLAK | G14: MNX TK | H14: G761B | I14: CIURA PAWEŁ | J14: 43831
A15: NOWAK EMIL | B15: 1019 | C15: TM MNX2 | D15: MNX TK | E15: G761D | F15: MARCIN PYŹLAK | G15: MNX TK | H15: G761B | I15: CIURA PAWEŁ | J15: 43831
A16: DZIEDZIC STANISŁAW | B16: 405 | C16: TL MNX2 | D16: MNX TK | E16: G761B | F16: ANDRZEJ WARCHOŁ | G16: MNX TK | H16: G761D | I16: PYŹLAK MARCIN | J16: 43831
A17: JĘCZMIEŃ WIKTOR | B17: 1761 | C17: TM MNX2 | D17: MNX TK | E17: G761A | F17: PUZIAK ROMUALD | G17: MNX TK | H17: G761D | I17: PYŹLAK MARCIN | J17: 43831
A18: STAWIARSKI DANIEL | B18: 1031 | C18: TL MNX | D18: MNX TK | E18: G761A | F18: ROMUALD PUZIAK | G18: MNX TK | H18: G7TN1 | I18: WARCHOŁ ANDRZEJ | J18: 43831
... A20: KREMIENOWSKI MAREK | B20: 886 | C20: TM MNX2 | D20: MNX WN | E20: G711B | F20: ANDRZEJ GOŁEK | G20: MNX WN | H20: G711A | I20: CZARKOWSKI NORBERT | J20: 43831
A21: #N/A | B21: 2125 | C21: #N/A | D21: MNX WN | E21: G7715 | F21: PASTERNAK MARIUSZ | G21: MNX WN | H21: G711C | I21: HORADCZUK | J21: 43831
A22: BARAN WIESŁAW | B22: 453 | C22: TM MNX2 | D22: MNX WN | E22: G711C | F22: HORADCZUK | G22: MNX WN | H22: G7715 | I22: PASTERNAK MARIUSZ | J22: 43831
A23: HOMEL SEBASTIAN | B23: 124 | C23: GRL2 | D23: EPKM | E23: T0001 | F23: MACIEJ KOMORNICZAK | G23: MTB0 | H23: G403B | I23: CZYŻ SYLWESTER | J23: 43831
A24: MAZIAKOWSKI TOMASZ | B24: 1818 | C24: SSPC | D24: PC&PURCHASING | E24: E1300 | F24: HOLA PIOTR | G24: QE | H24: F1ULT | I24: MIARA SEBASTIAN | J24: 43831
A25: FERENC BOGUSŁAW | B25: 669 | C25: TL MNX | D25: MNX WN | E25: G711A | F25: NORBERT CZARKOWSKI | G25: MNX WN | H25: G7HVT | I25: ŁASZEWKI TOMASZ | J25: 43831
A26: KOTOWSKI ARTUR | B26: 1982 | C26: TM MNX | D26: MNX WN | E26: G711A | F26: NORBERT CZARKOWSKI | G26: MNX WN | H26: G7HVT | I26: SŁAWOMIR SACHER | J26: 43831
A27: KLAG GRZEGORZ | B27: 1076 | C27: AC ASM | D27: ENGINEERING | E27: H1SSH | F27: ŁUKASZ SUROWIEC | G27: ENGINEERING | H27: H1HV3 | I27: SUROWIEC ŁUKASZ | J27: 43831
A28: GAŁA WIKTOR | B28: 2177 | C28: ENG | D28: ENGINEERING | E28: H1SSH | F28: ŁUKASZ SUROWIEC | G28: ENGINEERING | H28: H1HV3 | I28: SUROWIEC ŁUKASZ | J28: 43831
A29: SUCHAN TOMASZ | B29: 2763 | C29: SENG | D29: ENGINEERING | E29: H1SSH | F29: ŁUKASZ SUROWIEC | G29: ENGINEERING | H29: H1HV3 | I29: SUROWIEC ŁUKASZ | J29: 43831
A30: WICHA MARIUSZ | B30: 2975 | C30: ENG | D30: ENGINEERING | E30: H1SSH | F30: ŁUKASZ SUROWIEC | G30: ENGINEERING | H30: H1HV3 | I30: SUROWIEC ŁUKASZ | J30: 43831
A31: DUDIAK GRZEGORZ | B31: 276 | C31: TL2 | D31: MTB0 | E31: G401A | F31: KRZYSZTOF PEREK | G31: HV PJT | H31: V201A | I31: CHRZANOWSKI JAROSŁAW | J31: 43831
A32: CABAŁA WIESŁAW | B32: 1562 | C32: AC GRL | D32: EPKM | E32: T0001 | F32: HOMEL SEBASTIAN | G32: HV PJT | H32: V203A | I32: SZUPER TOMASZ | J32: 43831
A33: PARAKIEWICZ PAWEŁ | B33: 839 | C33: TL2 | D33: HV | E33: V103A | F33: KRZYSZTOF MAŁECKI | G33: HV PJT | H33: V203A | I33: SZUPER TOMASZ | J33: 43831
... A51: CZUCZUK PIOTR | B51: 268 | C51: GRL | D51: MTB0 | E51: G404B | F51: CZYŻ SYLWESTER | G51: MTB0 | H51: G405B | I51: SYLWESTER CZYŻ | J51: 43837
A52: OPASAŁA PAWEŁ | B52: 984 | C52: TM2 | D52: EC60 | E52: G803A | F52: BŁASZCZYK ROBERT | G52: #N/A | H52: G830A | I52: MAJCHER PRZEMYSŁAW | J52: 43837
A53: OSMAŃSKI DARIUSZ | B53: 2464 | C53: TM | D53: EC60 | E53: G804A | F53: TOKARSKI ARTUR | G53: #N/A | H53: G830A | I53: MAJCHER PRZEMYSŁAW | J53: 43837
A54: MAŁGORZATA MAZUREK | B54: 70551 | C54: TCZ | D54: MTB0 | E54: G401B | F54: CZYŻOWSKI MARIUSZ | G54: MTB0 | H54: G401A | I54: PEREK KRZYSZTOF | J54: 43839
A55: DANIEL ŚLUSARZ | B55: 70550 | C55: TCZ | D55: MTB0 | E55: G401A | F55: PEREK KRZYSZTOF | G55: MTB0 | H55: G401B | I55: CZYŻOWSKI MARIUSZ | J55: 43839
A56: KOWALIK ARTUR | B56: 1012 | C56: TM2 | D56: CASTING | E56: G501B | F56: PIOTROWSKI WOJCIECH | G56: CASTING | H56: G501A | I56: ŚLUCZKA TYMOTEUSZ | J56: 43843
A57: MARCIŃCZYK PIOTR | B57: 732 | C57: TM2 | D57: CASTING | E57: G501A | F57: ŚLUCZKA TYMOTEUSZ | G57: CASTING | H57: G501B | I57: PIOTROWSKI WOJCIECH | J57: 43843
A58: DANIEL CZYŻ | B58: 70553 | C58: TCZ | D58: CASTING | E58: G501A | F58: ŚLUCZKA TYMOTEUSZ | G58: CASTING | H58: G501C | I58: DAWID KRZYSZTOF | J58: 43843
...

Sheet LISTA 12
A1: Numer | B1: Nazwisko | C1: Imię | D1: Kolumna10 | E1: Kolumna10 | F1: Kolumna11 | G1: Przełożony | H1: Naz, Imię
A2: 5 | B2: ANDRASZ | C2: JAROSŁAW | D2: G6000 | E2: G6000 | F2: MNG | G2: FIGZAŁ CEZARY | H2: ANDRASZ JAROSŁAW
A3: 7 | B3: CZYŻ | C3: SYLWESTER | D3: G4000 | E3: G4000 | F3: ASM | G3: DEMESZUK KRZYSZTOF | H3: CZYŻ SYLWESTER
A4: 8 | B4: DEMESZUK | C4: KRZYSZTOF | D4: G4000 | E4: G4000 | F4: MNG | G4: SWAŁTEK BENIAMIN | H4: DEMESZUK KRZYSZTOF
A5: 11 | B5: JAGODZIŃSKI | C5: KAZIMIERZ | D5: G0001 | E5: G0001 | F5: GM | G5: OCZKOWSKI ZBIGNIEW | H5: JAGODZIŃSKI KAZIMIERZ
A6: 13 | B6: OWCARZ | C6: GRZEGORZ | D6: G0700 | E6: G0700 | F6: GM | G6: USAMI SHINJI | H6: OWCARZ GRZEGORZ
A7: 15 | B7: WITOSŁAWSKI | C7: ROMAN | D7: G712B | E7: G712B | F7: GRL MNX2 | G7: PICEK KRZYSZTOF | H7: WITOSŁAWSKI ROMAN
A8: 16 | B8: DRĄG | C8: DARIUSZ | D8: G715A | E8: G715A | F8: TL MNX2 | G8: PASTERNAK MARIUSZ | H8: DRĄG DARIUSZ
A9: 17 | B9: FLEGEL | C9: PIOTR | D9: F208A | E9: F208A | F9: GRL | G9: NOWAKOWSKI PRZEMYSŁAW | H9: FLEGEL PIOTR
A10: 18 | B10: MAJCHER | C10: PRZEMYSŁAW | D10: V1000 | E10: V1000 | F10: MNG | G10: FIGZAŁ CEZARY | H10: MAJCHER PRZEMYSŁAW
A11: 20 | B11: OKOPNIAK | C11: ARTUR | D11: G5000 | E11: G5000 | F11: MNG | G11: SWAŁTEK BENIAMIN | H11: OKOPNIAK ARTUR
A12: 21 | B12: RYŁKO | C12: RYSZARD | D12: G712D | E12: G712D | F12: GRL MNX | G12: PICEK KRZYSZTOF | H12: RYŁKO RYSZARD
A13: 24 | B13: DĘBEK | C13: PAWEŁ | D13: G4000 | E13: G4000 | F13: ASM | G13: DEMESZUK KRZYSZTOF | H13: DĘBEK PAWEŁ
... A25: 51 | B25: CZARKOWSKI | C25: NORBERT | D25: G711A | E25: G711A | F25: GRL MNX | G25: FIGIELA ROBERT | H25: CZARKOWSKI NORBERT
A26: 53 | B26: SZKARADEK | C26: GRZEGORZ | D26: V3000 | E26: V3000 | F26: ASM | G26: JACHYM ANDRZEJ | H26: SZKARADEK GRZEGORZ | L26: Józefiak Roksana | M26: =UPPER(L26) -> JÓZEFIAK ROKSANA
A27: 54 | B27: BADIURA | C27: KRZYSZTOF | D27: G615B | E27: G615B | F27: GRL | G27: URODA PAWEŁ | H27: BADIURA KRZYSZTOF | L27: Olszewska Mariola | M27: =UPPER(L27) -> OLSZEWSKA MARIOLA
A28: 55 | B28: LATAŁA | C28: PIOTR | D28: G201B | E28: G201B | F28: GRL2 | G28: DEMESZUK KRZYSZTOF | H28: LATAŁA PIOTR | L28: Smolarczyk Beata | M28: =UPPER(L28) -> SMOLARCZYK BEATA
A29: 57 | B29: GOŁEK | C29: ANDRZEJ | D29: G7HVT | E29: G7HVT | F29: GRL MNX2 | G29: ZĘBEK ANDRZEJ | H29: GOŁEK ANDRZEJ
A30: 58 | B30: JABŁOŃSKI | C30: GRZEGORZ | D30: G7HV3 | E30: G7HV3 | F30: TL MNX2 | G30: MOLSKI SYLWESTER | H30: JABŁOŃSKI GRZEGORZ
A31: 60 | B31: JACHYM | C31: ANDRZEJ | D31: V0000 | E31: V0000 | F31: AGM | G31: USAMI SHINJI | H31: JACHYM ANDRZEJ
A32: 63 | B32: SROKA | C32: ANNA | D32: A1400 | E32: A1400 | F32: ASM | G32: GÓRSKI GRZEGORZ | H32: SROKA ANNA
A33: 65 | B33: KOPEĆ | C33: SŁAWOMIR | D33: G718A | E33: G718A | F33: GRL | G33: WOJERZ MICHAŁ | H33: KOPEĆ SŁAWOMIR
A34: 67 | B34: SUCHECKI | C34: PRZEMYSŁAW | D34: P3000 | E34: P3000 | F34: GRL2 | G34: KOMORNICZAK MACIEJ | H34: SUCHECKI PRZEMYSŁAW
A35: 68 | B35: NOWAKOWSKI | C35: PRZEMYSŁAW | D35: F2000 | E35: F2000 | F35: ASM | G35: TOCZKO DARIUSZ | H35: NOWAKOWSKI PRZEMYSŁAW
A36: 69 | B36: MUSIAŁ | C36: GRZEGORZ | D36: TN000 | E36: TN000 | F36: ASM | G36: JACHYM ANDRZEJ | H36: MUSIAŁ GRZEGORZ
A37: 70 | B37: WIESZCZECIŃSKI | C37: KRYSTIAN | D37: B5000 | E37: B5000 | F37: GRL | G37: KRÓL MARCIN | H37: WIESZCZECIŃSKI KRYSTIAN
A38: 72 | B38: SMARZYŃSKI | C38: ADAM | D38: G711A | E38: G711A | F38: TM MNX2 | G38: CZARKOWSKI NORBERT | H38: SMARZYŃSKI ADAM
A39: 74 | B39: FIAŁKOWSKI | C39: JACEK | D39: S0001 | E39: S0001 | F39: GRL | G39: BYRA ZBIGNIEW | H39: FIAŁKOWSKI JACEK
A40: 75 | B40: JANKOWSKI | C40: DAMIAN | D40: F2TNA | E40: F2TNA | F40: TL2 | G40: SZCZEPAŃSKI RAFAŁ | H40: JANKOWSKI DAMIAN
... A105: 172 | B105: STADNIK | C105: MIROSŁAW | D105: V103C | E105: V103C | F105: GRL2 | G105: NOWAK BOGDAN | H105: STADNIK MIROSŁAW
A106: 177 | B106: RYCZEK | C106: SEBASTIAN | D106: G307B | E106: G307B | F106: GRL | H106: RYCZEK SEBASTIAN
A107: 179 | B107: JÓZEFIAK | C107: PAWEŁ | D107: B1300 | E107: B1300 | F107: GRL2 | G107: SZUDZIŃSKA MAGDALENA | H107: JÓZEFIAK PAWEŁ
A108: 180 | B108: TOKARSKI | C108: ARTUR | D108: G804A | E108: G804A | F108: GRL | G108: KLECHA PRZEMYSŁAW | H108: TOKARSKI ARTUR
A109: 182 | B109: CHOJNACKI | C109: KRZYSZTOF | D109: G616B | E109: G616B | F109: GRL | G109: URODA PAWEŁ | H109: CHOJNACKI KRZYSZTOF
A110: 185 | B110: MALINOWSKI | C110: MARIUSZ | D110: E31VA | E110: E31VA | F110: TL | G110: WEISS DARIUSZ | H110: MALINOWSKI MARIUSZ
A111: 187 | B111: KWIATKOWSKI | C111: RAFAŁ | D111: V203A | E111: V203A | F111: TL | G111: SZUPER TOMASZ | H111: KWIATKOWSKI RAFAŁ
A112: 188 | B112: MAKSYMOWICZ | C112: SEBASTIAN | D112: V303A | E112: V303A | F112: TL2 | G112: KOLASIŃSKI PAWEŁ | H112: MAKSYMOWICZ SEBASTIAN
A113: 189 | B113: PODSIEDLIK | C113: SEBASTIAN | D113: E113B | E113: E113B | F113: GRL | G113: WESOŁEK WIESŁAW | H113: PODSIEDLIK SEBASTIAN
A114: 190 | B114: SURMIAK | C114: ANDRZEJ | D114: G3000 | E114: G3000 | F114: AC ASM | G114: PIWOWARCZYK MARCIN | H114: SURMIAK ANDRZEJ
A115: 191 | B115: KROPIEWNICKI | C115: KRZYSZTOF | D115: V102C | E115: V102C | F115: TL | G115: OPALSKI RADOSŁAW | H115: KROPIEWNICKI KRZYSZTOF
...

Sheet lista 1
A1: Numer | B1: Nazwisko | C1: Imię | D1: =B1&" "&C1 -> Nazwisko Imię | E1: Stanowisko
A2: 2 | B2: MIKOŁAJCZAK | C2: DARIUSZ | D2: MIKOŁAJCZAK DARIUSZ | E2: DIR
A3: 5 | B3: ANDRASZ | C3: JAROSŁAW | D3: ANDRASZ JAROSŁAW | E3: MNG
A4: 7 | B4: CZYŻ | C4: SYLWESTER | D4: CZYŻ SYLWESTER | E4: ASM
A5: 8 | B5: DEMESZUK | C5: KRZYSZTOF | D5: DEMESZUK KRZYSZTOF | E5: MNG
A6: 11 | B6: JAGODZIŃSKI | C6: KAZIMIERZ | D6: JAGODZIŃSKI KAZIMIERZ | E6: GM
A7: 13 | B7: OWCARZ | C7: GRZEGORZ | D7: OWCARZ GRZEGORZ | E7: GM
A8: 15 | B8: WITOSŁAWSKI | C8: ROMAN | D8: WITOSŁAWSKI ROMAN | E8: GRL MNX2
A9: 16 | B9: DRĄG | C9: DARIUSZ | D9: DRĄG DARIUSZ | E9: TL MNX2
A10: 17 | B10: FLEGEL | C10: PIOTR | D10: FLEGEL PIOTR | E10: GRL
A11: 18 | B11: MAJCHER | C11: PRZEMYSŁAW | D11: MAJCHER PRZEMYSŁAW | E11: MNG
A12: 20 | B12: OKOPNIAK | C12: ARTUR | D12: OKOPNIAK ARTUR | E12: MNG
A13: 21 | B13: RYŁKO | C13: RYSZARD | D13: RYŁKO RYSZARD | E13: GRL MNX
... A2043: 70768 | B2043: AVILOVA | C2043: OLENA | D2043: AVILOVA OLENA | E2043: TCZ

Sheet lista 3
A1: CC | B1: Obszar
A2: 1 | B2: TEEM | C2: TEEM
A3: 2 | B3: TEEM | C3: TEEM
A4: 3 | B4: MANPOWER SHARING | C4: MNX
A5: 4 | B5: MANPOWER SHARING | C5: MNX
A6: A1100 | B6: CORPORATE AFFAIRS | C6: OFFICE
A7: A1200 | B7: PURCHASING | C7: OFFICE
A8: A1400 | B8: ADMINISTRATION & CORPORATE SERVICES | C8: OFFICE
A9: AR11A | B9: ARTO- SPECIAL KAIZEN TEAM | C9: ARTO
A10: AR11B | B10: ARTO- SPECIAL KAIZEN TEAM | C10: ARTO
A11: AR11C | B11: ARTO- SPECIAL KAIZEN TEAM | C11: ARTO
A12: AR41A | C12: ARTO
A13: AR41B | C13: ARTO
A14: AR41C | C14: ARTO
A15: AR42A | C15: ARTO
A16: AR42B | C16: ARTO
A17: AR42C | C17: ARTO
A18: AR43A | C18: ARTO
A19: AR43B | B19: ARTO - Karakuri | C19: ARTO - Karakuri
A20: AR43C | B20: ARTO - Kakuato | C20: ARTO - Kakuato
A21: ART00 | B21: ARTO- SPECIAL KAIZEN TEAM - GENERAL | C21: ARTO
A22: B1000 | B22: HUMAN RESOURCES | C22: OFFICE
A23: B1300 | B23: EMPLOYEES RELATIONS | C23: OFFICE
A24: B1400 | B24: COMPENSATION, BENEFITS & SYSTEMS | C24: OFFICE
A25: B3000 | B25: HR DEVELOPMENT | C25: OFFICE
A26: B3100 | B26: ORGANISATION DEVELOPMENT | C26: OFFICE
A27: B3200 | B27: TRAINING | C27: OFFICE
A28: B5000 | B28: TRADE UNION | C28: OFFICE
A29: C1000 | B29: ACCOUNTING & FINANCE GENERAL | C29: OFFICE
A30: C1100 | B30: ACCOUNTING | C30: OFFICE
... A118: G0146 | B118: Production Management | C118: Production
B119: Production Management | C119: Production
A120: V101A | C120: Hybrid
A121: V101B | C121: Hybrid
A122: V101C | C122: Hybrid | H122: V1000 | I122: HV OFFICE | J122: OFFICE
A123: V102A | C123: Hybrid | H123: V1020 | I123: HV | J123: HV TRAINING
A124: V102B | C124: Hybrid | H124: V103A | I124: HV | J124: Hybrid
A125: V102C | C125: Hybrid | H125: V102A | I125: HV | J125: Hybrid
A126: V103A | C126: Hybrid | H126: V101A | I126: HV | J126: Hybrid
A127: V103B | C127: Hybrid | H127: G5PRO | I127: HV PJT | J127: Hybrid
...

Sheet lista obszary
A1: CC | B1: Obszar | C1: ee
A2: 3 | B2: MANPOWER SHARING | C2: MNX
A3: 4 | B3: MANPOWER SHARING | C3: MNX
A4: A1100 | B4: ADMINISTRATION & CORPORATE SERVICES | C4: OFFICE
A5: A1200 | B5: PC&PURCHASING | C5: OFFICE
A6: A1300 | B6: ADMINISTRATION & CORPORATE SERVICES | C6: OFFICE
A7: A1400 | B7: ADMINISTRATION & CORPORATE SERVICES | C7: OFFICE
A8: AR11A | B8: ARTO | C8: ARTO
A9: AR11B | B9: ARTO | C9: ARTO
A10: AR11C | B10: ARTO | C10: ARTO
A11: AR41A | B11: ARTO | C11: ARTO
A12: AR41B | B12: ARTO | C12: ARTO
A13: AR41C | B13: ARTO | C13: ARTO
A14: AR42A | B14: ARTO | C14: ARTO
A15: AR42B | B15: ARTO | C15: ARTO
... A354: G901C | B354: CASTING | C354: DMC
A355: G0350 | B355: Production Management
A356: G0001 | B356: Production Management
A357: G7715 | B357: MNX WN
A358: F1HSS | B358: QC
A359: G6994 | B359: ENGINES
A360: F25VA | B360: QC
A361: E3715 | B361: IL
A362: TNGA | B362: TNGA
A363: A1000 | B363: ADMINISTRATION & CORPORATE SERVICES | C363: OFFICE
A364: A1500 | B364: GA CP
A365: C0000
A366: E0000
A367: E3TNA | B367: IL
A368: F1TN1 | B368: QE
A369: F2SVB | B369: QC
A370: F2SVC | B370: QC
A371: F2TNA | B371: QC
A372: G0700
A373: G7HV3 | B373: MNX WN
A374: G7TN1 | B374: MNX TK
A375: H1100 | B375: ENGINEERING | C375: OFFICE
A376: H1HV3 | B376: ENGINEERING | C376: OFFICE
A377: H1TNO | B377: ENGINEERING | C377: OFFICE
A378: H1TN1 | B378: ENGINEERING | C378: OFFICE
...
